2023-01-07 14:15:35,038 ERROR: Exception on /documents [GET] [in C:\Users\Mohan\AppData\Local\Programs\Python\Python310\lib\site-packages\flask\app.py:1741]
Traceback (most recent call last):
  File "C:\Users\Mohan\AppData\Local\Programs\Python\Python310\lib\site-packages\flask\app.py", line 2525, in wsgi_app
    response = self.full_dispatch_request()
  File "C:\Users\Mohan\AppData\Local\Programs\Python\Python310\lib\site-packages\flask\app.py", line 1822, in full_dispatch_request
    rv = self.handle_user_exception(e)
  File "C:\Users\Mohan\AppData\Local\Programs\Python\Python310\lib\site-packages\flask\app.py", line 1820, in full_dispatch_request
    rv = self.dispatch_request()
  File "C:\Users\Mohan\AppData\Local\Programs\Python\Python310\lib\site-packages\flask\app.py", line 1796, in dispatch_request
    return self.ensure_sync(self.view_functions[rule.endpoint])(**view_args)
  File "C:\Users\Mohan\AppData\Local\Programs\Python\Python310\lib\site-packages\flask_login\utils.py", line 290, in decorated_view
    return current_app.ensure_sync(func)(*args, **kwargs)
  File "C:\Users\Mohan\Documents\DMS-0.22 - v5\app\main\routes.py", line 100, in documents
    post = Post.query.filter_by(Post.timestamp.desc()).first_or_404()
TypeError: Query.filter_by() takes 1 positional argument but 2 were given
2023-01-07 14:24:04,023 INFO: DMS startup [in C:\Users\Mohan\Documents\DMS-0.22 - v5\app\__init__.py:88]
2023-01-07 14:24:10,179 ERROR: Exception on /documents [GET] [in C:\Users\Mohan\AppData\Local\Programs\Python\Python310\lib\site-packages\flask\app.py:1741]
Traceback (most recent call last):
  File "C:\Users\Mohan\AppData\Local\Programs\Python\Python310\lib\site-packages\flask\app.py", line 2525, in wsgi_app
    response = self.full_dispatch_request()
  File "C:\Users\Mohan\AppData\Local\Programs\Python\Python310\lib\site-packages\flask\app.py", line 1822, in full_dispatch_request
    rv = self.handle_user_exception(e)
  File "C:\Users\Mohan\AppData\Local\Programs\Python\Python310\lib\site-packages\flask\app.py", line 1820, in full_dispatch_request
    rv = self.dispatch_request()
  File "C:\Users\Mohan\AppData\Local\Programs\Python\Python310\lib\site-packages\flask\app.py", line 1796, in dispatch_request
    return self.ensure_sync(self.view_functions[rule.endpoint])(**view_args)
  File "C:\Users\Mohan\AppData\Local\Programs\Python\Python310\lib\site-packages\flask_login\utils.py", line 290, in decorated_view
    return current_app.ensure_sync(func)(*args, **kwargs)
  File "C:\Users\Mohan\Documents\DMS-0.22 - v5\app\main\routes.py", line 100, in documents
    post = Post.query.filter_by(Post.id).first_or_404()
TypeError: Query.filter_by() takes 1 positional argument but 2 were given
2023-01-07 14:24:30,370 INFO: DMS startup [in C:\Users\Mohan\Documents\DMS-0.22 - v5\app\__init__.py:88]
2023-01-07 14:24:35,552 ERROR: Exception on /documents [GET] [in C:\Users\Mohan\AppData\Local\Programs\Python\Python310\lib\site-packages\flask\app.py:1741]
Traceback (most recent call last):
  File "C:\Users\Mohan\AppData\Local\Programs\Python\Python310\lib\site-packages\flask\app.py", line 2525, in wsgi_app
    response = self.full_dispatch_request()
  File "C:\Users\Mohan\AppData\Local\Programs\Python\Python310\lib\site-packages\flask\app.py", line 1822, in full_dispatch_request
    rv = self.handle_user_exception(e)
  File "C:\Users\Mohan\AppData\Local\Programs\Python\Python310\lib\site-packages\flask\app.py", line 1820, in full_dispatch_request
    rv = self.dispatch_request()
  File "C:\Users\Mohan\AppData\Local\Programs\Python\Python310\lib\site-packages\flask\app.py", line 1796, in dispatch_request
    return self.ensure_sync(self.view_functions[rule.endpoint])(**view_args)
  File "C:\Users\Mohan\AppData\Local\Programs\Python\Python310\lib\site-packages\flask_login\utils.py", line 290, in decorated_view
    return current_app.ensure_sync(func)(*args, **kwargs)
  File "C:\Users\Mohan\Documents\DMS-0.22 - v5\app\main\routes.py", line 100, in documents
    post = Post.query.filter_by(Post.id)
TypeError: Query.filter_by() takes 1 positional argument but 2 were given
2023-01-07 14:24:57,820 INFO: DMS startup [in C:\Users\Mohan\Documents\DMS-0.22 - v5\app\__init__.py:88]
2023-01-07 14:25:01,237 ERROR: Exception on /documents [GET] [in C:\Users\Mohan\AppData\Local\Programs\Python\Python310\lib\site-packages\flask\app.py:1741]
Traceback (most recent call last):
  File "C:\Users\Mohan\AppData\Local\Programs\Python\Python310\lib\site-packages\flask\app.py", line 2525, in wsgi_app
    response = self.full_dispatch_request()
  File "C:\Users\Mohan\AppData\Local\Programs\Python\Python310\lib\site-packages\flask\app.py", line 1822, in full_dispatch_request
    rv = self.handle_user_exception(e)
  File "C:\Users\Mohan\AppData\Local\Programs\Python\Python310\lib\site-packages\flask\app.py", line 1820, in full_dispatch_request
    rv = self.dispatch_request()
  File "C:\Users\Mohan\AppData\Local\Programs\Python\Python310\lib\site-packages\flask\app.py", line 1796, in dispatch_request
    return self.ensure_sync(self.view_functions[rule.endpoint])(**view_args)
  File "C:\Users\Mohan\AppData\Local\Programs\Python\Python310\lib\site-packages\flask_login\utils.py", line 290, in decorated_view
    return current_app.ensure_sync(func)(*args, **kwargs)
  File "C:\Users\Mohan\Documents\DMS-0.22 - v5\app\main\routes.py", line 116, in documents
    form.approval_by_vao.data = post.approval_by_vao
AttributeError: 'BaseQuery' object has no attribute 'approval_by_vao'
2023-01-07 14:59:22,460 INFO: DMS startup [in C:\Users\Mohan\Documents\DMS-0.22 - v5\app\__init__.py:88]
2023-01-07 14:59:26,138 ERROR: Exception on /documents [GET] [in C:\Users\Mohan\AppData\Local\Programs\Python\Python310\lib\site-packages\flask\app.py:1741]
Traceback (most recent call last):
  File "C:\Users\Mohan\AppData\Local\Programs\Python\Python310\lib\site-packages\flask\app.py", line 2525, in wsgi_app
    response = self.full_dispatch_request()
  File "C:\Users\Mohan\AppData\Local\Programs\Python\Python310\lib\site-packages\flask\app.py", line 1822, in full_dispatch_request
    rv = self.handle_user_exception(e)
  File "C:\Users\Mohan\AppData\Local\Programs\Python\Python310\lib\site-packages\flask\app.py", line 1820, in full_dispatch_request
    rv = self.dispatch_request()
  File "C:\Users\Mohan\AppData\Local\Programs\Python\Python310\lib\site-packages\flask\app.py", line 1796, in dispatch_request
    return self.ensure_sync(self.view_functions[rule.endpoint])(**view_args)
  File "C:\Users\Mohan\AppData\Local\Programs\Python\Python310\lib\site-packages\flask_login\utils.py", line 290, in decorated_view
    return current_app.ensure_sync(func)(*args, **kwargs)
  File "C:\Users\Mohan\Documents\DMS-0.22 - v5\app\main\routes.py", line 116, in documents
    form.approval_by_vao.data = post.approval_by_vao
AttributeError: 'BaseQuery' object has no attribute 'approval_by_vao'
2023-01-07 14:59:29,712 ERROR: Exception on /documents [GET] [in C:\Users\Mohan\AppData\Local\Programs\Python\Python310\lib\site-packages\flask\app.py:1741]
Traceback (most recent call last):
  File "C:\Users\Mohan\AppData\Local\Programs\Python\Python310\lib\site-packages\flask\app.py", line 2525, in wsgi_app
    response = self.full_dispatch_request()
  File "C:\Users\Mohan\AppData\Local\Programs\Python\Python310\lib\site-packages\flask\app.py", line 1822, in full_dispatch_request
    rv = self.handle_user_exception(e)
  File "C:\Users\Mohan\AppData\Local\Programs\Python\Python310\lib\site-packages\flask\app.py", line 1820, in full_dispatch_request
    rv = self.dispatch_request()
  File "C:\Users\Mohan\AppData\Local\Programs\Python\Python310\lib\site-packages\flask\app.py", line 1796, in dispatch_request
    return self.ensure_sync(self.view_functions[rule.endpoint])(**view_args)
  File "C:\Users\Mohan\AppData\Local\Programs\Python\Python310\lib\site-packages\flask_login\utils.py", line 290, in decorated_view
    return current_app.ensure_sync(func)(*args, **kwargs)
  File "C:\Users\Mohan\Documents\DMS-0.22 - v5\app\main\routes.py", line 116, in documents
    form.approval_by_vao.data = post.approval_by_vao
AttributeError: 'BaseQuery' object has no attribute 'approval_by_vao'
2023-01-07 15:03:55,253 INFO: DMS startup [in C:\Users\Mohan\Documents\DMS-0.22 - v5\app\__init__.py:88]
2023-01-07 15:26:22,337 INFO: DMS startup [in C:\Users\Mohan\Documents\DMS-0.22 - v5\app\__init__.py:88]
2023-01-07 15:26:33,179 ERROR: Exception on /documents [GET] [in C:\Users\Mohan\AppData\Local\Programs\Python\Python310\lib\site-packages\flask\app.py:1741]
Traceback (most recent call last):
  File "C:\Users\Mohan\AppData\Local\Programs\Python\Python310\lib\site-packages\flask\app.py", line 2525, in wsgi_app
    response = self.full_dispatch_request()
  File "C:\Users\Mohan\AppData\Local\Programs\Python\Python310\lib\site-packages\flask\app.py", line 1822, in full_dispatch_request
    rv = self.handle_user_exception(e)
  File "C:\Users\Mohan\AppData\Local\Programs\Python\Python310\lib\site-packages\flask\app.py", line 1820, in full_dispatch_request
    rv = self.dispatch_request()
  File "C:\Users\Mohan\AppData\Local\Programs\Python\Python310\lib\site-packages\flask\app.py", line 1796, in dispatch_request
    return self.ensure_sync(self.view_functions[rule.endpoint])(**view_args)
  File "C:\Users\Mohan\AppData\Local\Programs\Python\Python310\lib\site-packages\flask_login\utils.py", line 290, in decorated_view
    return current_app.ensure_sync(func)(*args, **kwargs)
  File "C:\Users\Mohan\Documents\DMS-0.22 - v5\app\main\routes.py", line 108, in documents
    form.approval_by_vao.data = post.approval_by_vao
AttributeError: 'BaseQuery' object has no attribute 'approval_by_vao'
2023-01-07 21:56:18,134 INFO: DMS startup [in C:\Users\Mohan\Documents\DMS-0.22 - v5\app\__init__.py:88]
