2023-01-06 23:37:56,770 ERROR: Exception on /documents [GET] [in C:\Users\Mohan\AppData\Local\Programs\Python\Python310\lib\site-packages\flask\app.py:1741]
Traceback (most recent call last):
  File "C:\Users\Mohan\AppData\Local\Programs\Python\Python310\lib\site-packages\flask\app.py", line 2525, in wsgi_app
    response = self.full_dispatch_request()
  File "C:\Users\Mohan\AppData\Local\Programs\Python\Python310\lib\site-packages\flask\app.py", line 1822, in full_dispatch_request
    rv = self.handle_user_exception(e)
  File "C:\Users\Mohan\AppData\Local\Programs\Python\Python310\lib\site-packages\flask\app.py", line 1820, in full_dispatch_request
    rv = self.dispatch_request()
  File "C:\Users\Mohan\AppData\Local\Programs\Python\Python310\lib\site-packages\flask\app.py", line 1796, in dispatch_request
    return self.ensure_sync(self.view_functions[rule.endpoint])(**view_args)
  File "C:\Users\Mohan\AppData\Local\Programs\Python\Python310\lib\site-packages\flask_login\utils.py", line 290, in decorated_view
    return current_app.ensure_sync(func)(*args, **kwargs)
  File "C:\Users\Mohan\Documents\DMS-0.22 - v5\app\main\routes.py", line 114, in documents
    form.approval_by_vao.data = current_user.approval_by_vao
AttributeError: 'User' object has no attribute 'approval_by_vao'
2023-01-06 23:45:52,842 INFO: DMS startup [in C:\Users\Mohan\Documents\DMS-0.22 - v5\app\__init__.py:88]
2023-01-06 23:47:19,587 ERROR: Exception on /documents [GET] [in C:\Users\Mohan\AppData\Local\Programs\Python\Python310\lib\site-packages\flask\app.py:1741]
Traceback (most recent call last):
  File "C:\Users\Mohan\AppData\Local\Programs\Python\Python310\lib\site-packages\flask\app.py", line 2525, in wsgi_app
    response = self.full_dispatch_request()
  File "C:\Users\Mohan\AppData\Local\Programs\Python\Python310\lib\site-packages\flask\app.py", line 1822, in full_dispatch_request
    rv = self.handle_user_exception(e)
  File "C:\Users\Mohan\AppData\Local\Programs\Python\Python310\lib\site-packages\flask\app.py", line 1820, in full_dispatch_request
    rv = self.dispatch_request()
  File "C:\Users\Mohan\AppData\Local\Programs\Python\Python310\lib\site-packages\flask\app.py", line 1796, in dispatch_request
    return self.ensure_sync(self.view_functions[rule.endpoint])(**view_args)
  File "C:\Users\Mohan\AppData\Local\Programs\Python\Python310\lib\site-packages\flask_login\utils.py", line 290, in decorated_view
    return current_app.ensure_sync(func)(*args, **kwargs)
TypeError: documents() missing 1 required positional argument: 'username'
2023-01-06 23:53:05,140 INFO: DMS startup [in C:\Users\Mohan\Documents\DMS-0.22 - v5\app\__init__.py:88]
2023-01-06 23:53:09,401 ERROR: Exception on /documents [GET] [in C:\Users\Mohan\AppData\Local\Programs\Python\Python310\lib\site-packages\flask\app.py:1741]
Traceback (most recent call last):
  File "C:\Users\Mohan\AppData\Local\Programs\Python\Python310\lib\site-packages\flask\app.py", line 2525, in wsgi_app
    response = self.full_dispatch_request()
  File "C:\Users\Mohan\AppData\Local\Programs\Python\Python310\lib\site-packages\flask\app.py", line 1822, in full_dispatch_request
    rv = self.handle_user_exception(e)
  File "C:\Users\Mohan\AppData\Local\Programs\Python\Python310\lib\site-packages\flask\app.py", line 1820, in full_dispatch_request
    rv = self.dispatch_request()
  File "C:\Users\Mohan\AppData\Local\Programs\Python\Python310\lib\site-packages\flask\app.py", line 1796, in dispatch_request
    return self.ensure_sync(self.view_functions[rule.endpoint])(**view_args)
  File "C:\Users\Mohan\AppData\Local\Programs\Python\Python310\lib\site-packages\flask_login\utils.py", line 290, in decorated_view
    return current_app.ensure_sync(func)(*args, **kwargs)
  File "C:\Users\Mohan\Documents\DMS-0.22 - v5\app\main\routes.py", line 115, in documents
    form.approval_by_vao.data = posts.approval_by_vao
AttributeError: 'Pagination' object has no attribute 'approval_by_vao'
2023-01-06 23:54:00,732 INFO: DMS startup [in C:\Users\Mohan\Documents\DMS-0.22 - v5\app\__init__.py:88]
2023-01-06 23:54:03,733 ERROR: Exception on /documents [GET] [in C:\Users\Mohan\AppData\Local\Programs\Python\Python310\lib\site-packages\flask\app.py:1741]
Traceback (most recent call last):
  File "C:\Users\Mohan\AppData\Local\Programs\Python\Python310\lib\site-packages\flask\app.py", line 2525, in wsgi_app
    response = self.full_dispatch_request()
  File "C:\Users\Mohan\AppData\Local\Programs\Python\Python310\lib\site-packages\flask\app.py", line 1822, in full_dispatch_request
    rv = self.handle_user_exception(e)
  File "C:\Users\Mohan\AppData\Local\Programs\Python\Python310\lib\site-packages\flask\app.py", line 1820, in full_dispatch_request
    rv = self.dispatch_request()
  File "C:\Users\Mohan\AppData\Local\Programs\Python\Python310\lib\site-packages\flask\app.py", line 1796, in dispatch_request
    return self.ensure_sync(self.view_functions[rule.endpoint])(**view_args)
  File "C:\Users\Mohan\AppData\Local\Programs\Python\Python310\lib\site-packages\flask_login\utils.py", line 290, in decorated_view
    return current_app.ensure_sync(func)(*args, **kwargs)
  File "C:\Users\Mohan\Documents\DMS-0.22 - v5\app\main\routes.py", line 105, in documents
    form = ApprovalForm(posts)
  File "C:\Users\Mohan\AppData\Local\Programs\Python\Python310\lib\site-packages\wtforms\form.py", line 208, in __call__
    return type.__call__(cls, *args, **kwargs)
  File "C:\Users\Mohan\AppData\Local\Programs\Python\Python310\lib\site-packages\flask_wtf\form.py", line 73, in __init__
    super().__init__(formdata=formdata, **kwargs)
  File "C:\Users\Mohan\AppData\Local\Programs\Python\Python310\lib\site-packages\wtforms\form.py", line 286, in __init__
    self.process(formdata, obj, data=data, **kwargs)
  File "C:\Users\Mohan\AppData\Local\Programs\Python\Python310\lib\site-packages\wtforms\form.py", line 127, in process
    field.process(formdata, data, extra_filters=field_extra_filters)
  File "C:\Users\Mohan\AppData\Local\Programs\Python\Python310\lib\site-packages\wtforms\fields\core.py", line 322, in process
    if self.name in formdata:
TypeError: argument of type 'Pagination' is not iterable
2023-01-06 23:55:08,778 INFO: DMS startup [in C:\Users\Mohan\Documents\DMS-0.22 - v5\app\__init__.py:88]
2023-01-06 23:55:13,157 ERROR: Exception on /documents [GET] [in C:\Users\Mohan\AppData\Local\Programs\Python\Python310\lib\site-packages\flask\app.py:1741]
Traceback (most recent call last):
  File "C:\Users\Mohan\AppData\Local\Programs\Python\Python310\lib\site-packages\flask\app.py", line 2525, in wsgi_app
    response = self.full_dispatch_request()
  File "C:\Users\Mohan\AppData\Local\Programs\Python\Python310\lib\site-packages\flask\app.py", line 1822, in full_dispatch_request
    rv = self.handle_user_exception(e)
  File "C:\Users\Mohan\AppData\Local\Programs\Python\Python310\lib\site-packages\flask\app.py", line 1820, in full_dispatch_request
    rv = self.dispatch_request()
  File "C:\Users\Mohan\AppData\Local\Programs\Python\Python310\lib\site-packages\flask\app.py", line 1796, in dispatch_request
    return self.ensure_sync(self.view_functions[rule.endpoint])(**view_args)
  File "C:\Users\Mohan\AppData\Local\Programs\Python\Python310\lib\site-packages\flask_login\utils.py", line 290, in decorated_view
    return current_app.ensure_sync(func)(*args, **kwargs)
  File "C:\Users\Mohan\Documents\DMS-0.22 - v5\app\main\routes.py", line 116, in documents
    form.approval_by_vao.data = post.approval_by_vao
AttributeError: 'BaseQuery' object has no attribute 'approval_by_vao'
2023-01-06 23:56:13,406 INFO: DMS startup [in C:\Users\Mohan\Documents\DMS-0.22 - v5\app\__init__.py:88]
2023-01-06 23:56:15,328 ERROR: Exception on /documents [GET] [in C:\Users\Mohan\AppData\Local\Programs\Python\Python310\lib\site-packages\flask\app.py:1741]
Traceback (most recent call last):
  File "C:\Users\Mohan\AppData\Local\Programs\Python\Python310\lib\site-packages\flask\app.py", line 2525, in wsgi_app
    response = self.full_dispatch_request()
  File "C:\Users\Mohan\AppData\Local\Programs\Python\Python310\lib\site-packages\flask\app.py", line 1822, in full_dispatch_request
    rv = self.handle_user_exception(e)
  File "C:\Users\Mohan\AppData\Local\Programs\Python\Python310\lib\site-packages\flask\app.py", line 1820, in full_dispatch_request
    rv = self.dispatch_request()
  File "C:\Users\Mohan\AppData\Local\Programs\Python\Python310\lib\site-packages\flask\app.py", line 1796, in dispatch_request
    return self.ensure_sync(self.view_functions[rule.endpoint])(**view_args)
  File "C:\Users\Mohan\AppData\Local\Programs\Python\Python310\lib\site-packages\flask_login\utils.py", line 290, in decorated_view
    return current_app.ensure_sync(func)(*args, **kwargs)
  File "C:\Users\Mohan\Documents\DMS-0.22 - v5\app\main\routes.py", line 100, in documents
    post = Post.query.filter_by(Post.timestamp.desc()).first_or_404()
TypeError: Query.filter_by() takes 1 positional argument but 2 were given
2023-01-07 14:15:19,666 INFO: DMS startup [in C:\Users\Mohan\Documents\DMS-0.22 - v5\app\__init__.py:88]
