2023-01-08 11:07:59,613 ERROR: Exception on /documents [POST] [in C:\Users\Mohan\AppData\Local\Programs\Python\Python310\lib\site-packages\flask\app.py:1741]
Traceback (most recent call last):
  File "C:\Users\Mohan\AppData\Local\Programs\Python\Python310\lib\site-packages\flask\app.py", line 2525, in wsgi_app
    response = self.full_dispatch_request()
  File "C:\Users\Mohan\AppData\Local\Programs\Python\Python310\lib\site-packages\flask\app.py", line 1822, in full_dispatch_request
    rv = self.handle_user_exception(e)
  File "C:\Users\Mohan\AppData\Local\Programs\Python\Python310\lib\site-packages\flask\app.py", line 1820, in full_dispatch_request
    rv = self.dispatch_request()
  File "C:\Users\Mohan\AppData\Local\Programs\Python\Python310\lib\site-packages\flask\app.py", line 1796, in dispatch_request
    return self.ensure_sync(self.view_functions[rule.endpoint])(**view_args)
  File "C:\Users\Mohan\AppData\Local\Programs\Python\Python310\lib\site-packages\flask_login\utils.py", line 290, in decorated_view
    return current_app.ensure_sync(func)(*args, **kwargs)
  File "C:\Users\Mohan\Documents\DMS-0.22 - v5\app\main\routes.py", line 115, in documents
    return render_template('document.html', title=_('Documents'))
  File "C:\Users\Mohan\AppData\Local\Programs\Python\Python310\lib\site-packages\flask\templating.py", line 147, in render_template
    return _render(app, template, context)
  File "C:\Users\Mohan\AppData\Local\Programs\Python\Python310\lib\site-packages\flask\templating.py", line 130, in _render
    rv = template.render(context)
  File "C:\Users\Mohan\AppData\Local\Programs\Python\Python310\lib\site-packages\jinja2\environment.py", line 1301, in render
    self.environment.handle_exception()
  File "C:\Users\Mohan\AppData\Local\Programs\Python\Python310\lib\site-packages\jinja2\environment.py", line 936, in handle_exception
    raise rewrite_traceback_stack(source=source)
  File "C:\Users\Mohan\Documents\DMS-0.22 - v5\app\templates\document.html", line 2, in top-level template code
    {% import 'bootstrap/wtf.html' as wtf %}
  File "C:\Users\Mohan\Documents\DMS-0.22 - v5\app\templates\base.html", line 1, in top-level template code
    {% extends 'bootstrap/base.html' %}
  File "C:\Users\Mohan\AppData\Local\Programs\Python\Python310\lib\site-packages\flask_bootstrap\templates\bootstrap\base.html", line 1, in top-level template code
    {% block doc -%}
  File "C:\Users\Mohan\AppData\Local\Programs\Python\Python310\lib\site-packages\flask_bootstrap\templates\bootstrap\base.html", line 4, in block 'doc'
    {%- block html %}
  File "C:\Users\Mohan\AppData\Local\Programs\Python\Python310\lib\site-packages\flask_bootstrap\templates\bootstrap\base.html", line 20, in block 'html'
    {% block body -%}
  File "C:\Users\Mohan\AppData\Local\Programs\Python\Python310\lib\site-packages\flask_bootstrap\templates\bootstrap\base.html", line 23, in block 'body'
    {% block content -%}
  File "C:\Users\Mohan\Documents\DMS-0.22 - v5\app\templates\base.html", line 79, in block 'content'
    {% block app_content %}{% endblock %}
  File "C:\Users\Mohan\Documents\DMS-0.22 - v5\app\templates\document.html", line 5, in block 'app_content'
    {% include '_post.html' %}
  File "C:\Users\Mohan\Documents\DMS-0.22 - v5\app\templates\_post.html", line 4, in top-level template code
    <a href="{{ url_for('main.user', username=post.author.username) }}">
  File "C:\Users\Mohan\AppData\Local\Programs\Python\Python310\lib\site-packages\jinja2\environment.py", line 485, in getattr
    return getattr(obj, attribute)
jinja2.exceptions.UndefinedError: 'post' is undefined
2023-01-08 11:12:06,095 INFO: DMS startup [in C:\Users\Mohan\Documents\DMS-0.22 - v5\app\__init__.py:88]
2023-01-08 11:14:34,693 INFO: DMS startup [in C:\Users\Mohan\Documents\DMS-0.22 - v5\app\__init__.py:88]
2023-01-08 11:18:17,064 ERROR: Exception on /documents [GET] [in C:\Users\Mohan\AppData\Local\Programs\Python\Python310\lib\site-packages\flask\app.py:1741]
Traceback (most recent call last):
  File "C:\Users\Mohan\AppData\Local\Programs\Python\Python310\lib\site-packages\flask\app.py", line 2525, in wsgi_app
    response = self.full_dispatch_request()
  File "C:\Users\Mohan\AppData\Local\Programs\Python\Python310\lib\site-packages\flask\app.py", line 1822, in full_dispatch_request
    rv = self.handle_user_exception(e)
  File "C:\Users\Mohan\AppData\Local\Programs\Python\Python310\lib\site-packages\flask\app.py", line 1820, in full_dispatch_request
    rv = self.dispatch_request()
  File "C:\Users\Mohan\AppData\Local\Programs\Python\Python310\lib\site-packages\flask\app.py", line 1796, in dispatch_request
    return self.ensure_sync(self.view_functions[rule.endpoint])(**view_args)
  File "C:\Users\Mohan\AppData\Local\Programs\Python\Python310\lib\site-packages\flask_login\utils.py", line 290, in decorated_view
    return current_app.ensure_sync(func)(*args, **kwargs)
  File "C:\Users\Mohan\Documents\DMS-0.22 - v5\app\main\routes.py", line 118, in documents
    form.approval_by_vao.data = post.approval_by_vao
AttributeError: 'NoneType' object has no attribute 'approval_by_vao'
2023-01-08 11:18:22,789 ERROR: Exception on /documents [GET] [in C:\Users\Mohan\AppData\Local\Programs\Python\Python310\lib\site-packages\flask\app.py:1741]
Traceback (most recent call last):
  File "C:\Users\Mohan\AppData\Local\Programs\Python\Python310\lib\site-packages\flask\app.py", line 2525, in wsgi_app
    response = self.full_dispatch_request()
  File "C:\Users\Mohan\AppData\Local\Programs\Python\Python310\lib\site-packages\flask\app.py", line 1822, in full_dispatch_request
    rv = self.handle_user_exception(e)
  File "C:\Users\Mohan\AppData\Local\Programs\Python\Python310\lib\site-packages\flask\app.py", line 1820, in full_dispatch_request
    rv = self.dispatch_request()
  File "C:\Users\Mohan\AppData\Local\Programs\Python\Python310\lib\site-packages\flask\app.py", line 1796, in dispatch_request
    return self.ensure_sync(self.view_functions[rule.endpoint])(**view_args)
  File "C:\Users\Mohan\AppData\Local\Programs\Python\Python310\lib\site-packages\flask_login\utils.py", line 290, in decorated_view
    return current_app.ensure_sync(func)(*args, **kwargs)
  File "C:\Users\Mohan\Documents\DMS-0.22 - v5\app\main\routes.py", line 118, in documents
    form.approval_by_vao.data = post.approval_by_vao
AttributeError: 'NoneType' object has no attribute 'approval_by_vao'
2023-01-08 11:18:31,806 ERROR: Exception on /documents [GET] [in C:\Users\Mohan\AppData\Local\Programs\Python\Python310\lib\site-packages\flask\app.py:1741]
Traceback (most recent call last):
  File "C:\Users\Mohan\AppData\Local\Programs\Python\Python310\lib\site-packages\flask\app.py", line 2525, in wsgi_app
    response = self.full_dispatch_request()
  File "C:\Users\Mohan\AppData\Local\Programs\Python\Python310\lib\site-packages\flask\app.py", line 1822, in full_dispatch_request
    rv = self.handle_user_exception(e)
  File "C:\Users\Mohan\AppData\Local\Programs\Python\Python310\lib\site-packages\flask\app.py", line 1820, in full_dispatch_request
    rv = self.dispatch_request()
  File "C:\Users\Mohan\AppData\Local\Programs\Python\Python310\lib\site-packages\flask\app.py", line 1796, in dispatch_request
    return self.ensure_sync(self.view_functions[rule.endpoint])(**view_args)
  File "C:\Users\Mohan\AppData\Local\Programs\Python\Python310\lib\site-packages\flask_login\utils.py", line 290, in decorated_view
    return current_app.ensure_sync(func)(*args, **kwargs)
  File "C:\Users\Mohan\Documents\DMS-0.22 - v5\app\main\routes.py", line 118, in documents
    form.approval_by_vao.data = post.approval_by_vao
AttributeError: 'NoneType' object has no attribute 'approval_by_vao'
2023-01-08 11:18:34,854 ERROR: Exception on /documents [GET] [in C:\Users\Mohan\AppData\Local\Programs\Python\Python310\lib\site-packages\flask\app.py:1741]
Traceback (most recent call last):
  File "C:\Users\Mohan\AppData\Local\Programs\Python\Python310\lib\site-packages\flask\app.py", line 2525, in wsgi_app
    response = self.full_dispatch_request()
  File "C:\Users\Mohan\AppData\Local\Programs\Python\Python310\lib\site-packages\flask\app.py", line 1822, in full_dispatch_request
    rv = self.handle_user_exception(e)
  File "C:\Users\Mohan\AppData\Local\Programs\Python\Python310\lib\site-packages\flask\app.py", line 1820, in full_dispatch_request
    rv = self.dispatch_request()
  File "C:\Users\Mohan\AppData\Local\Programs\Python\Python310\lib\site-packages\flask\app.py", line 1796, in dispatch_request
    return self.ensure_sync(self.view_functions[rule.endpoint])(**view_args)
  File "C:\Users\Mohan\AppData\Local\Programs\Python\Python310\lib\site-packages\flask_login\utils.py", line 290, in decorated_view
    return current_app.ensure_sync(func)(*args, **kwargs)
  File "C:\Users\Mohan\Documents\DMS-0.22 - v5\app\main\routes.py", line 118, in documents
    form.approval_by_vao.data = post.approval_by_vao
AttributeError: 'NoneType' object has no attribute 'approval_by_vao'
2023-01-08 11:39:33,904 INFO: DMS startup [in C:\Users\Mohan\Documents\DMS-0.22 - v5\app\__init__.py:88]
2023-01-08 13:01:25,831 INFO: DMS startup [in C:\Users\Mohan\Documents\DMS-0.22 - v5\app\__init__.py:88]
2023-01-08 13:04:05,257 INFO: DMS startup [in C:\Users\Mohan\Documents\DMS-0.22 - v5\app\__init__.py:88]
2023-01-08 13:06:16,516 INFO: DMS startup [in C:\Users\Mohan\Documents\DMS-0.22 - v5\app\__init__.py:88]
